Workbook
Name anchor_src_columns_note: #REF!
Name anchor_src_columns_note: #REF!
Name anchor_src_columns_null: #REF!
Name anchor_src_columns_null: #REF!
Name anchor_src_columns_pk: #REF!
Name anchor_src_columns_pk: #REF!
Name anchor_src_columns_type: #REF!
Name anchor_src_columns_type: #REF!
Name anchor_tgt_columns_def: #REF!
Name anchor_tgt_columns_def: 'Source columns'!#REF!
Name anchor_tgt_columns_def: #REF!
Name anchor_tgt_columns_fk: #REF!
Name anchor_tgt_columns_fk: 'Source columns'!$H$1
Name anchor_tgt_columns_fk: #REF!
Name anchor_tgt_columns_note: #REF!
Name anchor_tgt_columns_note: 'Source columns'!$J$1
Name anchor_tgt_columns_note: #REF!
Name anchor_tgt_columns_null: #REF!
Name anchor_tgt_columns_null: 'Source columns'!$E$1
Name anchor_tgt_columns_null: #REF!
Name anchor_tgt_columns_pk: #REF!
Name anchor_tgt_columns_pk: 'Source columns'!$G$1
Name anchor_tgt_columns_pk: #REF!
Name anchor_tgt_columns_po: #REF!
Name anchor_tgt_columns_po: 'Source columns'!$F$1
Name anchor_tgt_columns_po: #REF!
Name anchor_tgt_columns_type: #REF!
Name anchor_tgt_columns_type: 'Source columns'!$D$1
Name anchor_tgt_columns_type: #REF!
Name anchor_tgt_tables_ntab: #REF!
Name anchor_tgt_tables_ntab: 'Target tables'!$E$1
Name anchor_tgt_tables_ntab: #REF!
Name anchor_tgt_tables_sa: #REF!
Name anchor_tgt_tables_sa: 'Target tables'!$D$1
Name anchor_tgt_tables_sa: #REF!
Name d: '[1]Target columns'!$D$1
Name first_value: Глоссарий!$I$1:$I$3
Name lst_src_columns: #REF!
Name lst_src_columns: #REF!
Name lst_tgt_columns: #REF!
Name lst_tgt_columns: 'Source columns'!$A:$J
Name lst_tgt_columns: #REF!
Name lst_tgt_tables: #REF!
Name lst_tgt_tables: 'Target tables'!$A:$E
Name lst_tgt_tables: #REF!
Name sff: '[1]Target columns'!$H$1
Name target_columns2: #REF!

Sheet Список изменений
A1: Версия | B1: Дата | C1: Измененный объект | D1: Изменение | E1: Автор | F1: Комментарий | G1: Номер патча
A2: 0.5 | B2: 45565 | C2: S2T, Source columns, Target tables, Target columns | D2: Добавлен атрибут в t_registry, добавлена таблица t_registry_type. Изменен тип поля rateSubsidyScheme_agreement | E2: Свиридова
A3: 0.6 | B3: 45573 | C3: S2T, Additional objects | D3: Добавлено условие фильтрации для таблицы t_agr_escrow_int_org. Изменен SQL-запрос для V_B3080000460001_legalEpkId | E3: Свиридова
A4: 0.7 | B4: 45574 | C4: S2T, Additional objects | D4: Добавлено условие фильтрации для таблицы t_agr_escrow_int_org. Изменен SQL-запрос для V_B3080000460001_escrowBranchCode | E4: Свиридова
A5: 0.8 | B5: 45595 | C5: Additional objects | D5: V_B3080000460001_developerLoanAgr | E5: Масальцева
A6: 0.8 | B6: 45595 | C6: Additional objects | D6: V_B3080000460001_externalRegistryId | E6: Масальцева
A7: 0.8 | B7: 45595 | C7: Additional objects | D7: V_B3080000460001_rateSubsidyScheme | E7: Масальцева
A8: 0.8 | B8: 45595 | C8: Additional objects | D8: V_B3080000460001_legalEpkId | E8: Масальцева
A9: 0.8 | B9: 45595 | C9: Additional objects | D9: V_B3080000460001_currency | E9: Масальцева
A10: 0.8 | B10: 45595 | C10: Additional objects | D10: V_B3080000460001_escrowBranchCode | E10: Масальцева
A11: 0.8 | B11: 45595 | C11: Additional objects | D11: V_B3080000460005_tariffs | E11: Масальцева
A12: 0.8 | B12: 45595 | C12: Additional objects | D12: V_B3080000460006_payments | E12: Масальцева
A13: 0.8 | B13: 45595 | C13: S2T | D13: t_agr_escrow (блок 530 ) | E13: Масальцева
... A59: 0.11 | B59: 45685 | C59: S2T | D59: Изменение имени таблицы b3080000460008_general_agreement_actual_limitschedule | E59: Свиридова
A60: 0.11 | B60: 45685 | C60: S2T | D60: t_registry | E60: Свиридова | F60: ГС исключение счетов резерва
A61: 0.11 | B61: 45685 | C61: Source columns | D61: Изменение имени таблицы b3080000460008_general_agreement_actual_limitschedule и названия поля external_id_uid (external_id) | E61: Свиридова
A62: 0.11 | B62: 45685 | C62: Метаданные для hadoop | D62: Изменение имени таблицы general_agreement_actual_limitschedule | E62: Свиридова
A63: 0.12 | B63: 45688 | C63: Метаданные для hadoop | D63: lcl_agreement_actual: новая таблица lcl_registry: новая таблица payments_2_0_posting: добавлены поля postingEvent.accountDebit.number + postingEvent.accountCredit.registerId + postingEvent.accountCredit.number + postingEvent.operationIdKt payments_2_0_posting: изменен json путь к атрибутам operationIdDt -> postingEvent.operationIdDt accountDebit.registerId -> postingEvent.accountDebit.registerId serviceId -> postingEvent.serviceId | E63: Афанасова
A64: 0.12 | B64: 45688 | C64: hadoop ->A | D64: a_000046_lcl_agreement_actual_dto: новая таблица a_000046_lcl_agreement_credit_contracts: новая таблица a_000046_lcl_agreement_supply_contracts: новая таблица a_000046_lcl_agreement_tariffs: новая таблица a_000046_lcl_agreement_applicant_fee_accounts: новая таблица a_000046_lcl_registry_dto: новая таблица | E64: Афанасова
A65: 0.12 | B65: 45688 | C65: А-слой->В-слой | D65: b3080000460009_lcl_agreement_actual_dto: новая таблица b3080000460010_lcl_agreement_credit_contracts: новая таблица b3080000460011_lcl_agreement_supply_contracts: новая таблица b3080000460012_lcl_agreement_tariffs: новая таблица b3080000460013_lcl_agreement_applicant_fee_accounts: новая таблица b3080000460014_lcl_registry_dto: новая таблица | E65: Афанасова
A66: 0.12 | B66: 45688 | C66: Source columns | D66: b3080000460009_lcl_agreement_actual_dto: новая таблица b3080000460010_lcl_agreement_credit_contracts: новая таблица b3080000460011_lcl_agreement_supply_contracts: новая таблица b3080000460012_lcl_agreement_tariffs: новая таблица b3080000460013_lcl_agreement_applicant_fee_accounts: новая таблица b3080000460013_lcl_registry_dto: новая таблица b3080000460006_payments_2_0_posting_dto: добавлены поля postingevent_accountdebit_number + postingevent_accountcredit_registerid + postingevent_accountcredit_number + postingevent_operationidkt | E66: Афанасова
A67: 0.13 | B67: 45692 | C67: Target columns | D67: t_agr_frame, изменено название поля start_dt на open_dt | E67: Свиридова
A68: 0.13 | B68: 45692 | C68: S2T | D68: t_agr_frame, изменено название поля start_dt на open_dt t_cust --добавлено условие deleted='N' для B-таблиц t_int_org --добавлено условие deleted='N' для B-таблиц, поле rn вынесено во внешний подзапрос (иначе были дубли) t_agr_escrow_int_org --при заполнени action_cd учитывается значение deleted='Y' t_optn_type --добавлено условие deleted='N' t_optn --Создана таблица n308000046_optn, заполняемая функцией sp308000046_bn_00840_optn. При заполнени action_cd учитывается значение deleted='Y'. t_optn$gls --Создана таблица n308000046_optn$gls, заполняемая функцией sp308000046_bn_00920_optn$gls. При заполнени action_cd учитывается значение deleted='Y'. t_cust_org_idfn --при заполнени action_cd учитывается значение deleted='Y' T_optn_fee_type --добавлено условие deleted='N' | E68: Свиридова
A69: 0.14 | B69: 45700 | C69: Source columns | D69: b3080000460006_payments_2_0_posting_dto: добавлено поле external_agreement_id | E69: Афанасова
A70: 0.14 | B70: 45700 | C70: s2t | D70: t_agr_accred | E70: Афанасова | F70: новый блок - Аккредитивы ЮЛ
A71: 0.14 | B71: 45700 | C71: s2t | D71: t_agr_accred_fin | E71: Афанасова | F71: новый блок - Аккредитивы ЮЛ
A72: 0.14 | B72: 45700 | C72: s2t | D72: t_accred_cover_type | E72: Афанасова | F72: новый блок - Аккредитивы ЮЛ
A73: 0.14 | B73: 45700 | C73: s2t | D73: t_time_period_type | E73: Афанасова | F73: новый блок - Аккредитивы ЮЛ
A74: 0.14 | B74: 45700 | C74: s2t | D74: t_agr_accred_type | E74: Афанасова | F74: новый блок - Аккредитивы ЮЛ
A75: 0.14 | B75: 45700 | C75: s2t | D75: t_accred_income_scheme | E75: Афанасова | F75: новый блок - Аккредитивы ЮЛ
A76: 0.14 | B76: 45700 | C76: s2t | D76: t_agr_accred_agr_cred | E76: Афанасова | F76: новый блок - Аккредитивы ЮЛ
A77: 0.14 | B77: 45700 | C77: s2t | D77: t_agr_accred_bank | E77: Афанасова | F77: новый блок - Аккредитивы ЮЛ
A78: 0.14 | B78: 45700 | C78: s2t | D78: t_agr_accred_contract | E78: Афанасова | F78: новый блок - Аккредитивы ЮЛ
A79: 0.14 | B79: 45700 | C79: s2t | D79: t_agr_accred_cust | E79: Афанасова | F79: новый блок - Аккредитивы ЮЛ
A80: 0.14 | B80: 45700 | C80: s2t | D80: t_agr_accred_int_org | E80: Афанасова | F80: новый блок - Аккредитивы ЮЛ
A81: 0.14 | B81: 45700 | C81: s2t | D81: t_bank | E81: Афанасова | F81: новый блок - Аккредитивы ЮЛ
... A99: 0.15 | B99: 45705 | C99: s2t | D99: t_agr_frame_int_org | E99: Свиридова | F99: изменено поле источника для agr_frame_id
A100: 0.15 | B100: 45705 | C100: Source columns | D100: b3080000460009_general_agreement_actual_dto: добавлено поле id | E100: Свиридова
A101: 0.15 | B101: 45705 | C101: Source columns | D101: b3080000460008_general_agreement_actual_limitschedule: добавлено поле id | E101: Свиридова
A102: 0.15 | B102: 45705 | C102: Target columns | D102: t_agr_frame: добавлено поле host_ext_id | E102: Свиридова
...

Sheet S2T
A2: № ПП | B2: Предметная область | C2: Описание целевой таблицы | D2: Таблица-приемник | E2: Тип данных поля приемника | F2: Первичный ключ? | G2: Внешний ключ? | H2: NULL? | I2: Описание поля приемника | J2: Поле приемника | K2: Таблица-источник | L2: Тип данных поля источника | M2: Описание поля источника | N2: Трансформация поля источника | O2: Дополнительная таблица-источник | P2: Условия соединения с дополнительной таблицей | Q2: K-таблица | R2: Условия соединения с K-таблицей | S2: Условия фильтрации исходного набора общий фильтр deleted = 'N' | T2: Пояснения к SQL исходного набора данных | U2: SQL исходного набора данных | V2: Название N-таблицы | W2: Роль в истории | X2: Since min date | Y2: Till max date | Z2: Restrict SQL | AA2: Accumulate | AB2: Full snapshot | AC2: Valid from workaround | AD2: Gaps | AE2: First value | AF2: СОД | AG2: Опции проекта | AH2: Кто менял | AI2: Дата | AJ2: Комментарии
A3: 10 | B3: Эскроу | C3: =IFERROR(VLOOKUP(D3,'Target tables'!A:B,2,0),"") -> Договор эскроу | D3: t_agr_escrow | E3: =IFERROR(VLOOKUP(D3&J3,'Target columns'!A:J,4,FALSE),"") -> UUID | F3: =IFERROR(VLOOKUP(D3&J3,'Target columns'!A:J,7,FALSE),"") -> Yes | G3: =IFERROR(VLOOKUP(D3&J3,'Target columns'!A:J,8,FALSE),"") -> No | H3: =IFERROR(VLOOKUP(D3&J3,'Target columns'!A:J,5,FALSE),"") -> NOT NULL | I3: =IFERROR(VLOOKUP(D3&J3,'Target columns'!A:J,10,FALSE),"") -> Идентификатор договора эскроу | J3: agr_escrow_id | K3: b3080000460001_escrow_legal214_agreement_actual_dto | L3: =IFERROR(VLOOKUP(UPPER(K3&N3), source_columns[], 4,0),"") -> uuid | M3: =IFERROR(VLOOKUP(UPPER(K3&N3), source_columns[], 7,0),"") -> Идентификатор договора эскроу | N3: escrowId_agreement_uid | V3: ="n308000046_"&IFERROR(VLOOKUP(D3, target_tables[], 5, 0),"<not found>") -> n308000046_agr_escrow | W3: Ключ | AF3: Снимок-снимок
A4: 20 | B4: Эскроу | C4: =IFERROR(VLOOKUP(D4,'Target tables'!A:B,2,0),"") -> Договор эскроу | D4: t_agr_escrow | E4: =IFERROR(VLOOKUP(D4&J4,'Target columns'!A:J,4,FALSE),"") -> DATE | F4: =IFERROR(VLOOKUP(D4&J4,'Target columns'!A:J,7,FALSE),"") -> No | G4: =IFERROR(VLOOKUP(D4&J4,'Target columns'!A:J,8,FALSE),"") -> No | H4: =IFERROR(VLOOKUP(D4&J4,'Target columns'!A:J,5,FALSE),"") -> NULL | I4: =IFERROR(VLOOKUP(D4&J4,'Target columns'!A:J,10,FALSE),"") -> Дата открытия договора эскроу | J4: open_dt | K4: b3080000460001_escrow_legal214_agreement_actual_dto | L4: =IFERROR(VLOOKUP(UPPER(K4&N5), source_columns[], 4,0),"") -> date | M4: =IFERROR(VLOOKUP(UPPER(K4&N4),source_columns[],7,0),"") -> Дата открытия договора эскроу | N4: openDate_agreement | V4: ="n308000046_"&IFERROR(VLOOKUP(D4,target_tables[],5,0),"<not found>") -> n308000046_agr_escrow | W4: -
A5: 30 | B5: Эскроу | C5: =IFERROR(VLOOKUP(D5,'Target tables'!A:B,2,0),"") -> Договор эскроу | D5: t_agr_escrow | E5: =IFERROR(VLOOKUP(D5&J5,'Target columns'!A:J,4,FALSE),"") -> DATE | F5: =IFERROR(VLOOKUP(D5&J5,'Target columns'!A:J,7,FALSE),"") -> No | G5: =IFERROR(VLOOKUP(D5&J5,'Target columns'!A:J,8,FALSE),"") -> No | H5: =IFERROR(VLOOKUP(D5&J5,'Target columns'!A:J,5,FALSE),"") -> NULL | I5: =IFERROR(VLOOKUP(D5&J5,'Target columns'!A:J,10,FALSE),"") -> Дата подписания договора эскроу | J5: signed_dt | K5: b3080000460001_escrow_legal214_agreement_actual_dto | L5: =IFERROR(VLOOKUP(UPPER(K5&N6),source_columns[],4,0),"") -> date | M5: =IFERROR(VLOOKUP(UPPER(K5&N5),source_columns[],7,0),"") -> Дата открытия договора эскроу | N5: openDate_agreement | V5: ="n308000046_"&IFERROR(VLOOKUP(D5,target_tables[],5,0),"<not found>") -> n308000046_agr_escrow | W5: -
A6: 40 | B6: Эскроу | C6: =IFERROR(VLOOKUP(D6,'Target tables'!A:B,2,0),"") -> Договор эскроу | D6: t_agr_escrow | E6: =IFERROR(VLOOKUP(D6&J6,'Target columns'!A:J,4,FALSE),"") -> DATE | F6: =IFERROR(VLOOKUP(D6&J6,'Target columns'!A:J,7,FALSE),"") -> No | G6: =IFERROR(VLOOKUP(D6&J6,'Target columns'!A:J,8,FALSE),"") -> No | H6: =IFERROR(VLOOKUP(D6&J6,'Target columns'!A:J,5,FALSE),"") -> NULL | I6: =IFERROR(VLOOKUP(D6&J6,'Target columns'!A:J,10,FALSE),"") -> Дата закрытия договора эскроу | J6: close_dt | K6: b3080000460001_escrow_legal214_agreement_actual_dto | L6: =IFERROR(VLOOKUP(UPPER(K6&N7),source_columns[],4,0),"") -> text | M6: =IFERROR(VLOOKUP(UPPER(K6&N6),source_columns[],7,0),"") -> Дата закрытия договора эскроу | N6: closeDate_agreement | V6: ="n308000046_"&IFERROR(VLOOKUP(D6,target_tables[],5,0),"<not found>") -> n308000046_agr_escrow | W6: -
A7: 50 | B7: Эскроу | C7: =IFERROR(VLOOKUP(D7,'Target tables'!A:B,2,0),"") -> Договор эскроу | D7: t_agr_escrow | E7: =IFERROR(VLOOKUP(D7&J7,'Target columns'!A:J,4,FALSE),"") -> TEXT | F7: =IFERROR(VLOOKUP(D7&J7,'Target columns'!A:J,7,FALSE),"") -> No | G7: =IFERROR(VLOOKUP(D7&J7,'Target columns'!A:J,8,FALSE),"") -> No | H7: =IFERROR(VLOOKUP(D7&J7,'Target columns'!A:J,5,FALSE),"") -> NULL | I7: =IFERROR(VLOOKUP(D7&J7,'Target columns'!A:J,10,FALSE),"") -> Номер договора эскроу | J7: agr_escrow_num | K7: b3080000460001_escrow_legal214_agreement_actual_dto | L7: =IFERROR(VLOOKUP(UPPER(K7&N7), source_columns[], 4,0),"") -> text | M7: =IFERROR(VLOOKUP(UPPER(K7&N7),source_columns[],7,0),"") -> Номер договора | N7: reference_agreement | V7: ="n308000046_"&IFERROR(VLOOKUP(D7,target_tables[],5,0),"<not found>") -> n308000046_agr_escrow | W7: -
A8: 60 | B8: Эскроу | C8: =IFERROR(VLOOKUP(D8,'Target tables'!A:B,2,0),"") -> Договор эскроу | D8: t_agr_escrow | E8: =IFERROR(VLOOKUP(D8&J8,'Target columns'!A:J,4,FALSE),"") -> TEXT | F8: =IFERROR(VLOOKUP(D8&J8,'Target columns'!A:J,7,FALSE),"") -> No | G8: =IFERROR(VLOOKUP(D8&J8,'Target columns'!A:J,8,FALSE),"") -> No | H8: =IFERROR(VLOOKUP(D8&J8,'Target columns'!A:J,5,FALSE),"") -> NULL | I8: =IFERROR(VLOOKUP(D8&J8,'Target columns'!A:J,10,FALSE),"") -> Идентификатор договора эскроу в системе-источнике | J8: host_agr_escrow_id | K8: b3080000460001_escrow_legal214_agreement_actual_dto | L8: =IFERROR(VLOOKUP(UPPER(K8&N8),source_columns[],4,0),"") -> text | M8: =IFERROR(VLOOKUP(UPPER(K8&N8),source_columns[],7,0),"") -> Идентификатор договора эскроу | N8: escrowId_agreement | V8: ="n308000046_"&IFERROR(VLOOKUP(D8,target_tables[],5,0),"<not found>") -> n308000046_agr_escrow | W8: -
A9: 70 | B9: Эскроу | C9: =IFERROR(VLOOKUP(D9,'Target tables'!A:B,2,0),"") -> Договор эскроу | D9: t_agr_escrow | E9: =IFERROR(VLOOKUP(D9&J9,'Target columns'!A:J,4,FALSE),"") -> DATE | F9: =IFERROR(VLOOKUP(D9&J9,'Target columns'!A:J,7,FALSE),"") -> No | G9: =IFERROR(VLOOKUP(D9&J9,'Target columns'!A:J,8,FALSE),"") -> No | H9: =IFERROR(VLOOKUP(D9&J9,'Target columns'!A:J,5,FALSE),"") -> NULL | I9: =IFERROR(VLOOKUP(D9&J9,'Target columns'!A:J,10,FALSE),"") -> Плановая дата ввода в эксплуатацию объекта строительства | J9: permission_explotation_plan_dt | K9: b3080000460001_escrow_legal214_agreement_actual_dto | L9: =IFERROR(VLOOKUP(UPPER(K9&N9),source_columns[],4,0),"") -> date | M9: =IFERROR(VLOOKUP(UPPER(K9&N9),source_columns[],7,0),"") -> Плановая дата ввода ОС в эксплуатацию | N9: completeEstimateDate_agreementObject | V9: ="n308000046_"&IFERROR(VLOOKUP(D9,target_tables[],5,0),"<not found>") -> n308000046_agr_escrow | W9: -
A10: 71 | B10: Эскроу | C10: =IFERROR(VLOOKUP(D10,'Target tables'!A:B,2,0),"") -> Договор эскроу | D10: t_agr_escrow | E10: =IFERROR(VLOOKUP(D10&J10,'Target columns'!A:J,4,FALSE),"") -> DATE | F10: =IFERROR(VLOOKUP(D10&J10,'Target columns'!A:J,7,FALSE),"") -> No | G10: =IFERROR(VLOOKUP(D10&J10,'Target columns'!A:J,8,FALSE),"") -> No | H10: =IFERROR(VLOOKUP(D10&J10,'Target columns'!A:J,5,FALSE),"") -> NULL | I10: =IFERROR(VLOOKUP(D10&J10,'Target columns'!A:J,10,FALSE),"") -> Срок депонирования объекта | J10: depositing_object_dt | K10: b3080000460001_escrow_legal214_agreement_actual_dto | L10: =IFERROR(VLOOKUP(UPPER(K10&N10),source_columns[],4,0),"") -> date | M10: =IFERROR(VLOOKUP(UPPER(K10&N10),source_columns[],7,0),"") -> Срок депонирования объекта | N10: estateObject_ExpireDate_agreementObject | V10: ="n308000046_"&IFERROR(VLOOKUP(D10,target_tables[],5,0),"<not found>") -> n308000046_agr_escrow
A11: 80 | B11: Эскроу | C11: =IFERROR(VLOOKUP(D11,'Target tables'!A:B,2,0),"") -> Договор эскроу | D11: t_agr_escrow | E11: =IFERROR(VLOOKUP(D11&J11,'Target columns'!A:J,4,FALSE),"") -> DECIMAL(26,4) | F11: =IFERROR(VLOOKUP(D11&J11,'Target columns'!A:J,7,FALSE),"") -> No | G11: =IFERROR(VLOOKUP(D11&J11,'Target columns'!A:J,8,FALSE),"") -> No | H11: =IFERROR(VLOOKUP(D11&J11,'Target columns'!A:J,5,FALSE),"") -> NULL | I11: =IFERROR(VLOOKUP(D11&J11,'Target columns'!A:J,10,FALSE),"") -> Сумма депонирования эскроу | J11: start_sum_crncy_amt | K11: b3080000460001_escrow_legal214_agreement_actual_dto | L11: =IFERROR(VLOOKUP(UPPER(K11&N11),source_columns[],4,0),"") -> decimal(38 , 16) | M11: =IFERROR(VLOOKUP(UPPER(K11&N11),source_columns[],7,0),"") -> Сумма депонирования | N11: escrowAmount_value_agreement | V11: ="n308000046_"&IFERROR(VLOOKUP(D11, target_tables[], 5, 0),"<not found>") -> n308000046_agr_escrow | W11: - | AJ11: В json максимальное значение - 10 в 15 степени
A12: 90 | B12: Эскроу | C12: =IFERROR(VLOOKUP(D12,'Target tables'!A:B,2,0),"") -> Договор эскроу | D12: t_agr_escrow | E12: =IFERROR(VLOOKUP(D12&J12,'Target columns'!A:J,4,FALSE),"") -> UUID | F12: =IFERROR(VLOOKUP(D12&J12,'Target columns'!A:J,7,FALSE),"") -> No | G12: =IFERROR(VLOOKUP(D12&J12,'Target columns'!A:J,8,FALSE),"") -> Yes | H12: =IFERROR(VLOOKUP(D12&J12,'Target columns'!A:J,5,FALSE),"") -> NULL | I12: =IFERROR(VLOOKUP(D12&J12,'Target columns'!A:J,10,FALSE),"") -> Идентификатор валюты | J12: crncy_id | K12: b3080000460001_escrow_legal214_agreement_actual_dto | L12: =IFERROR(VLOOKUP(UPPER(K12&N12),source_columns[],4,0),"") -> uuid | M12: =IFERROR(VLOOKUP(UPPER(K12&N12),source_columns[],7,0),"") -> Валюта суммы депонирования | N12: escrowAmount_currency_agreement_uid | V12: ="n308000046_"&IFERROR(VLOOKUP(D12,target_tables[],5,0),"<not found>") -> n308000046_agr_escrow | W12: -
A13: 100 | B13: Эскроу | C13: =IFERROR(VLOOKUP(D13,'Target tables'!A:B,2,0),"") -> Договор эскроу | D13: t_agr_escrow | E13: =IFERROR(VLOOKUP(D13&J13,'Target columns'!A:J,4,FALSE),"") -> UUID | F13: =IFERROR(VLOOKUP(D13&J13,'Target columns'!A:J,7,FALSE),"") -> No | G13: =IFERROR(VLOOKUP(D13&J13,'Target columns'!A:J,8,FALSE),"") -> Yes | H13: =IFERROR(VLOOKUP(D13&J13,'Target columns'!A:J,5,FALSE),"") -> NULL | I13: =IFERROR(VLOOKUP(D13&J13,'Target columns'!A:J,10,FALSE),"") -> Идентификатор схемы | J13: escrow_scheme_id | K13: b3080000460001_escrow_legal214_agreement_actual_dto | L13: =IFERROR(VLOOKUP(UPPER(K13&N13),source_columns[],4,0),"") -> uuid | M13: =IFERROR(VLOOKUP(UPPER(K13&N13),source_columns[],7,0),"") -> Схема субсидирования | N13: rateSubsidyScheme_agreement_uid | V13: ="n308000046_"&IFERROR(VLOOKUP(D13,target_tables[],5,0),"<not found>") -> n308000046_agr_escrow | W13: - | AJ13: По эскроу 214 - это схема субсидирования ставки
A14: 110 | B14: Эскроу | C14: =IFERROR(VLOOKUP(D14,'Target tables'!A:B,2,0),"") -> Договор эскроу | D14: t_agr_escrow | E14: =IFERROR(VLOOKUP(D14&J14,'Target columns'!A:J,4,FALSE),"") -> DATE | F14: =IFERROR(VLOOKUP(D14&J14,'Target columns'!A:J,7,FALSE),"") -> No | G14: =IFERROR(VLOOKUP(D14&J14,'Target columns'!A:J,8,FALSE),"") -> No | H14: =IFERROR(VLOOKUP(D14&J14,'Target columns'!A:J,5,FALSE),"") -> NULL | I14: =IFERROR(VLOOKUP(D14&J14,'Target columns'!A:J,10,FALSE),"") -> Плановая дата окончания/Срок условного депонирования договора | J14: expiration_dt | K14: b3080000460001_escrow_legal214_agreement_actual_dto | L14: =IFERROR(VLOOKUP(UPPER(K14&N14),source_columns[],4,0),"") -> date | M14: =IFERROR(VLOOKUP(UPPER(K14&N14),source_columns[],7,0),"") -> Срок депонирования договора | N14: expireDate_agreementObject | V14: ="n308000046_"&IFERROR(VLOOKUP(D14,target_tables[],5,0),"<not found>") -> n308000046_agr_escrow | W14: -
A15: 120 | B15: Эскроу | C15: =IFERROR(VLOOKUP(D15,'Target tables'!A:B,2,0),"") -> Договор эскроу | D15: t_agr_escrow | E15: =IFERROR(VLOOKUP(D15&J15,'Target columns'!A:J,4,FALSE),"") -> TEXT | F15: =IFERROR(VLOOKUP(D15&J15,'Target columns'!A:J,7,FALSE),"") -> No | G15: =IFERROR(VLOOKUP(D15&J15,'Target columns'!A:J,8,FALSE),"") -> No | H15: =IFERROR(VLOOKUP(D15&J15,'Target columns'!A:J,5,FALSE),"") -> NULL | I15: =IFERROR(VLOOKUP(D15&J15,'Target columns'!A:J,10,FALSE),"") -> Признак работы в рамках 214-ФЗ | J15: agr_214_fed_flag | K15: b3080000460001_escrow_legal214_agreement_actual_dto | L15: =IFERROR(VLOOKUP(UPPER(K15&N15),source_columns[],4,0),"") | M15: =IFERROR(VLOOKUP(UPPER(K15&N15),source_columns[],7,0),"") | N15: 'Y' | V15: ="n308000046_"&IFERROR(VLOOKUP(D15,target_tables[],5,0),"<not found>") -> n308000046_agr_escrow | W15: -
A16: 130 | B16: Эскроу | C16: =IFERROR(VLOOKUP(D16,'Target tables'!A:B,2,0),"") -> Кредитный договор | D16: t_agr_cred | E16: =IFERROR(VLOOKUP(D16&J16,'Target columns'!A:J,4,FALSE),"") -> UUID | F16: =IFERROR(VLOOKUP(D16&J16,'Target columns'!A:J,7,FALSE),"") -> Yes | G16: =IFERROR(VLOOKUP(D16&J16,'Target columns'!A:J,8,FALSE),"") -> No | H16: =IFERROR(VLOOKUP(D16&J16,'Target columns'!A:J,5,FALSE),"") -> NOT NULL | I16: =IFERROR(VLOOKUP(D16&J16,'Target columns'!A:J,10,FALSE),"") -> ИД кредитного договора с застройщиком | J16: agr_cred_id | K16: ETL | L16: uuid | M16: Номер кредитного договора | N16: developerLoanAgrNumber_cred_agreement_uid | S16: SELECT sub_2.agr_cred_id, sub_2.signed_dt, sub_2.agr_cred_num, sub_2.host_eks_agrmnt_id, sub_2.host_agr_cred_id, sub_2.input_file_id, sub_2.info_system_id, CASE WHEN sub_2.deleted_flag = 'Y'::text THEN 'D'::text ELSE sub_2.action_cd END AS action_cd, sub_2.deleted_flag, sub_2.workflow_run_id, '-103500130'::integer AS session_inst_id FROM ( SELECT sub_1.agr_cred_id, sub_1.signed_dt, sub_1.agr_cred_num, sub_1.host_eks_agrmnt_id, sub_1.host_agr_cred_id, sub_1.input_file_id, sub_1.info_system_id, sub_1.ctl_action AS action_cd, sub_1.deleted_flag, sub_1.workflow_run_id, row_number() OVER (PARTITION BY sub_1.agr_cred_id ORDER BY sub_1.signed_dt DESC, COALESCE(sub_1.host_agr_cred_id, '0'::text) DESC, COALESCE(sub_1.host_eks_agrmnt_id, '0'::text) DESC, sub_1.sys_date_create_or_update desc, sub_1.st ) AS rn FROM ( SELECT COALESCE(b3080000460001_escrow_legal214_agreement_actual_dto.devloanagrkulid_agreement_uid, b3080000460001_escrow_legal214_agreement_actual_dto.developerloanagrnumber_cred_agreement_uid) AS agr_cred_id, b3080000460001_escrow_legal214_agreement_actual_dto.developerloanagrdate_cred_agreement AS signed_dt, b3080000460001_escrow_legal214_agreement_actual_dto.developerloanagrnumber_cred_agreement AS agr_cred_num, b3080000460001_escrow_legal214_agreement_actual_dto.devloanagr_eksid_agreement AS host_eks_agrmnt_id, b3080000460001_escrow_legal214_agreement_actual_dto.devloanagrkulid_agreement AS host_agr_cred_id, 2 AS st, b3080000460001_escrow_legal214_agreement_actual_dto.sys_date_create_or_update, b3080000460001_escrow_legal214_agreement_actual_dto.input_file_id, b3080000460001_escrow_legal214_agreement_actual_dto.info_system_id, b3080000460001_escrow_legal214_agreement_actual_dto.ctl_action, b3080000460001_escrow_legal214_agreement_actual_dto.deleted_flag, b3080000460001_escrow_legal214_agreement_actual_dto.workflow_run_id FROM s_grnplm_as_t_didsd_308_db_stg.b3080000460001_escrow_legal214_agreement_actual_dto WHERE (b3080000460001_escrow_legal214_agreement_actual_dto.developerloanagrnumber_cred_agreement IS NOT NULL OR b3080000460001_escrow_legal214_agreement_actual_dto.devloanagrkulid_agreement IS NOT NULL) AND b3080000460001_escrow_legal214_agreement_actual_dto.deleted = 'N'::text UNION ALL SELECT COALESCE(b3080000460002_escrow_legalgk_agreement_actual_dto.depositorlegal_creditcontract_kulid_uid, b3080000460002_escrow_legalgk_agreement_actual_dto.depositorlegal_creditcontract_number_uid) AS agr_cred_id, b3080000460002_escrow_legalgk_agreement_actual_dto.depositorlegal_creditcontract_date AS signed_dt, b3080000460002_escrow_legalgk_agreement_actual_dto.depositorlegal_creditcontract_number AS agr_cred_num, b3080000460002_escrow_legalgk_agreement_actual_dto.depositorlegal_creditcontract_eks AS host_eks_agrmnt_id, b3080000460002_escrow_legalgk_agreement_actual_dto.depositorlegal_creditcontract_kulid AS host_agr_cred_id, 2 AS st, b3080000460002_escrow_legalgk_agreement_actual_dto.sys_date_create_or_update, b3080000460002_escrow_legalgk_agreement_actual_dto.input_file_id, b3080000460002_escrow_legalgk_agreement_actual_dto.info_system_id, b3080000460002_escrow_legalgk_agreement_actual_dto.ctl_action, b3080000460002_escrow_legalgk_agreement_actual_dto.deleted_flag, b3080000460002_escrow_legalgk_agreement_actual_dto.workflow_run_id FROM s_grnplm_as_t_didsd_308_db_stg.b3080000460002_escrow_legalgk_agreement_actual_dto WHERE (b3080000460002_escrow_legalgk_agreement_actual_dto.depositorlegal_creditcontract_number IS NOT NULL OR b3080000460002_escrow_legalgk_agreement_actual_dto.depositorlegal_creditcontract_kulid IS NOT NULL) AND b3080000460002_escrow_legalgk_agreement_actual_dto.deleted = 'N'::text UNION ALL SELECT COALESCE(b3080000460004_escrow_legalgk_beneficiarieslegal.creditcontract_l_kulid_uid, b3080000460004_escrow_legalgk_beneficiarieslegal.creditcontract_d_l_uid) AS agr_cred_id, b3080000460004_escrow_legalgk_beneficiarieslegal.creditcontract_l AS signed_dt, b3080000460004_escrow_legalgk_beneficiarieslegal.creditcontract_d_l AS agr_cred_num, b3080000460004_escrow_legalgk_beneficiarieslegal.creditcontract_l_eksid AS host_eks_agrmnt_id, b3080000460004_escrow_legalgk_beneficiarieslegal.creditcontract_l_kulid AS host_agr_cred_id, 2 AS st, b3080000460004_escrow_legalgk_beneficiarieslegal.sys_date_create_or_update, b3080000460004_escrow_legalgk_beneficiarieslegal.input_file_id, b3080000460004_escrow_legalgk_beneficiarieslegal.info_system_id, b3080000460004_escrow_legalgk_beneficiarieslegal.ctl_action, b3080000460004_escrow_legalgk_beneficiarieslegal.deleted_flag, b3080000460004_escrow_legalgk_beneficiarieslegal.workflow_run_id FROM s_grnplm_as_t_didsd_308_db_stg.b3080000460004_escrow_legalgk_beneficiarieslegal WHERE (b3080000460004_escrow_legalgk_beneficiarieslegal.creditcontract_d_l IS NOT NULL OR b3080000460004_escrow_legalgk_beneficiarieslegal.creditcontract_l_kulid IS NOT NULL) AND b3080000460004_escrow_legalgk_beneficiarieslegal.deleted = 'N'::text UNION ALL SELECT CASE WHEN COALESCE(btrim(b10.creditcontracts_idpprbkul), '-1'::text) = '-1'::text THEN b10.creditcontracts_number_uid ELSE b10.creditcontracts_idpprbkul_uid END AS agr_cred_id, b10.creditcontracts_date AS signed_dt, b10.creditcontracts_number AS agr_cred_num, b10.creditcontracts_eksid AS host_eks_agrmnt_id, b10.creditcontracts_idpprbkul AS host_agr_cred_id, CASE WHEN upper(b10.status) = 'INACTIVE'::text THEN 1 WHEN upper(b10.status) = 'CLOSED'::text THEN 10 ELSE 2 END AS st, b10.sys_date_create_or_update, b10.input_file_id, b10.info_system_id, 'I'::text AS ctl_action, 'N'::text AS deleted_flag, b10.workflow_run_id FROM s_grnplm_as_t_didsd_308_db_stg.b3080000460010_lcl_agreement_credit_contracts b10 WHERE (b10.creditcontracts_number_uid IS NOT NULL OR b10.creditcontracts_idpprbkul IS NOT NULL) AND b10.deleted = 'N'::text) sub_1) sub_2 WHERE sub_2.rn = 1 | V16: ="n308000046_"&IFERROR(VLOOKUP(D16,target_tables[],5,0),"<not found>") -> n308000046_agr_cred | W16: Ключ | AF16: Снимок-снимок | AJ16: это не ссылка на схему 700, на нее выйти технически невозможно
A17: 140 | B17: Эскроу | C17: =IFERROR(VLOOKUP(D17,'Target tables'!A:B,2,0),"") -> Кредитный договор | D17: t_agr_cred | E17: =IFERROR(VLOOKUP(D17&J17,'Target columns'!A:J,4,FALSE),"") -> DATE | F17: =IFERROR(VLOOKUP(D17&J17,'Target columns'!A:J,7,FALSE),"") -> No | G17: =IFERROR(VLOOKUP(D17&J17,'Target columns'!A:J,8,FALSE),"") -> No | H17: =IFERROR(VLOOKUP(D17&J17,'Target columns'!A:J,5,FALSE),"") -> NULL | I17: =IFERROR(VLOOKUP(D17&J17,'Target columns'!A:J,10,FALSE),"") -> Дата подписания договора | J17: signed_dt | K17: ETL | L17: date | M17: Дата кредитного договора | N17: developerLoanAgrDate_cred_agreement | V17: ="n308000046_"&IFERROR(VLOOKUP(D17,target_tables[],5,0),"<not found>") -> n308000046_agr_cred | W17: -
A18: 150 | B18: Эскроу | C18: =IFERROR(VLOOKUP(D18,'Target tables'!A:B,2,0),"") -> Кредитный договор | D18: t_agr_cred | E18: =IFERROR(VLOOKUP(D18&J18,'Target columns'!A:J,4,FALSE),"") -> TEXT | F18: =IFERROR(VLOOKUP(D18&J18,'Target columns'!A:J,7,FALSE),"") -> No | G18: =IFERROR(VLOOKUP(D18&J18,'Target columns'!A:J,8,FALSE),"") -> No | H18: =IFERROR(VLOOKUP(D18&J18,'Target columns'!A:J,5,FALSE),"") -> NULL | I18: =IFERROR(VLOOKUP(D18&J18,'Target columns'!A:J,10,FALSE),"") -> Номер договора | J18: agr_cred_num | K18: ETL | L18: text | M18: Номер кредитного договора | N18: developerLoanAgrNumber_cred_agreement | V18: ="n308000046_"&IFERROR(VLOOKUP(D18,target_tables[],5,0),"<not found>") -> n308000046_agr_cred | W18: -
A19: 160 | B19: Эскроу | C19: =IFERROR(VLOOKUP(D19,'Target tables'!A:B,2,0),"") -> Кредитный договор | D19: t_agr_cred | E19: =IFERROR(VLOOKUP(D19&J19,'Target columns'!A:J,4,FALSE),"") -> TEXT | F19: =IFERROR(VLOOKUP(D19&J19,'Target columns'!A:J,7,FALSE),"") -> No | G19: =IFERROR(VLOOKUP(D19&J19,'Target columns'!A:J,8,FALSE),"") -> No | H19: =IFERROR(VLOOKUP(D19&J19,'Target columns'!A:J,5,FALSE),"") -> NULL | I19: =IFERROR(VLOOKUP(D19&J19,'Target columns'!A:J,10,FALSE),"") -> ID договора в ЕКС | J19: host_eks_agrmnt_id | K19: ETL | L19: text | M19: ID договора в ЕКС | N19: devLoanAgr_EksId_agreement | V19: ="n308000046_"&IFERROR(VLOOKUP(D19,target_tables[],5,0),"<not found>") -> n308000046_agr_cred | W19: -
A20: 170 | B20: Эскроу | C20: =IFERROR(VLOOKUP(D20,'Target tables'!A:B,2,0),"") -> Кредитный договор | D20: t_agr_cred | E20: =IFERROR(VLOOKUP(D20&J20,'Target columns'!A:J,4,FALSE),"") -> TEXT | F20: =IFERROR(VLOOKUP(D20&J20,'Target columns'!A:J,7,FALSE),"") -> No | G20: =IFERROR(VLOOKUP(D20&J20,'Target columns'!A:J,8,FALSE),"") -> No | H20: =IFERROR(VLOOKUP(D20&J20,'Target columns'!A:J,5,FALSE),"") -> NULL | I20: =IFERROR(VLOOKUP(D20&J20,'Target columns'!A:J,10,FALSE),"") -> ИД договора в системе-источнике ППРБ.КЮЛ | J20: host_agr_cred_id | K20: ETL | L20: text | M20: ИД договора в системе-источнике ППРБ.КЮЛ | N20: devLoanAgrKulId_agreement | V20: ="n308000046_"&IFERROR(VLOOKUP(D20,target_tables[],5,0),"<not found>") -> n308000046_agr_cred | W20: -
A21: 180 | B21: Эскроу, ГС, Аккредитив, УПФ | C21: =IFERROR(VLOOKUP(D21,'Target tables'!A:B,2,0),"") -> Таблица регистров | D21: t_registry | E21: =IFERROR(VLOOKUP(D21&J21,'Target columns'!A:J,4,FALSE),"") -> UUID | F21: =IFERROR(VLOOKUP(D21&J21,'Target columns'!A:J,7,FALSE),"") -> Yes | G21: =IFERROR(VLOOKUP(D21&J21,'Target columns'!A:J,8,FALSE),"") -> No | H21: =IFERROR(VLOOKUP(D21&J21,'Target columns'!A:J,5,FALSE),"") -> NOT NULL | I21: =IFERROR(VLOOKUP(D21&J21,'Target columns'!A:J,10,FALSE),"") -> Идентификатор регистра | J21: registry_id | K21: ETL | L21: uuid | M21: ID регистра счёта | N21: registry_id | S21: select * from ( -- Эскроу 214 select externalRegistryId_escrow_accountDetails_uid as registry_id, externalRegistryId_escrow_accountDetails as host_registry_id, escrowId_agreement_uid as agr_escrow_id, null as agr_id, number_escrow_accountDetails, '00000000-0000-0000-0000-0000fffffc14' as registry_type_id, cast(sys_date_create_or_update as date) as start_dt, cast('9999-12-31' as date) as end_dt, row_number() over (partition by externalregistryid_escrow_accountdetails order by sys_date_create_or_update desc) as rn from s_grnplm_as_t_didsd_308_db_stg.b3080000460001_escrow_legal214_agreement_actual_dto where externalRegistryId_escrow_accountDetails is not null ) a where a.rn = 1 union all select * from ( -- Эскроу ГК select externalregistryid_uid as registry_id, externalregistryid as host_registry_id, escrowid_uid as agr_escrow_id, null as agr_id, null as number_escrow_accountDetails, '00000000-0000-0000-0000-0000fffffc13' as registry_type_id, cast(sys_date_create_or_update as date) as start_dt, cast('9999-12-31' as date) as end_dt, row_number() over (partition by externalregistryid order by sys_date_create_or_update desc) as rn from s_grnplm_as_t_didsd_308_db_stg.b3080000460002_escrow_legalgk_agreement_actual_dto where externalregistryid is not null ) a where a.rn = 1 union all -- Аккредитивы ЮЛ select o.registerid_uid as registry_id , o.registerid as host_registry_id , null::uuid as agr_escrow_id , o.agreementreference_uid as agr_id , o.accountevent_number as coa_num , '00000000-0000-0000-0000-0000fffffc11' as registry_type_id -- accred^Аккредитивы ЮЛ , cast(sys_date_create_or_update as date) as start_dt , cast('9999-12-31' as date) as end_dt from s_grnplm_as_t_didsd_308_db_stg.b3080000460007_payments_2_0_account_dto as o inner join s_grnplm_as_t_didsd_308_db_stg.b3080000460015_lcl_agreement_actual_dto as b on o.agreementreference = b.reference where 1 = 1 and o.registerid_uid is not null and coalesce(upper(o.systemid), '') <> upper('reserve-factory') union all select o.registerid_uid as registry_id , o.registerid as host_registry_id , null::uuid as agr_escrow_id , o.agreementreference_uid as agr_id , o.accountevent_number as coa_num , '00000000-0000-0000-0000-0000fffffc12' as registry_type_id -- reserve^Резервы , cast(sys_date_create_or_update as date) as start_dt , cast('9999-12-31' as date) as end_dt from s_grnplm_as_t_didsd_308_db_stg.b3080000460007_payments_2_0_account_dto as o inner join s_grnplm_as_t_didsd_308_db_stg.b3080000460015_lcl_agreement_actual_dto as b on o.agreementreference = b.reference where 1 = 1 and o.registerid_uid is not null and coalesce(upper(o.systemid), '') = upper('reserve-factory') --инкассо экспортное union all select o.registerid_uid as registry_id , o.registerid as host_registry_id , null::uuid as agr_escrow_id , o.agreementreference_uid as agr_id , o.accountevent_number as coa_num , '00000000-0000-0000-0000-0000fffffc0f' as registry_type_id -- -1009^exportinkasso^Эксп. Инкассо , cast(sys_date_create_or_update as date) as start_dt , cast('9999-12-31' as date) as end_dt from s_grnplm_as_t_didsd_308_db_stg.b3080000460007_payments_2_0_account_dto as o inner join s_grnplm_as_t_didsd_308_db_stg.b3080000460016_inkasso_export_agreement_actual_dto as b on o.agreementreference = b.reference where 1 = 1 and o.registerid_uid is not null and coalesce(upper(o.systemid), '') <> upper('reserve-factory') union all select o.registerid_uid as registry_id , o.registerid as host_registry_id , null::uuid as agr_escrow_id , o.agreementreference_uid as agr_id , o.accountevent_number as coa_num , '00000000-0000-0000-0000-0000fffffc12' as registry_type_id -- reserve^Резервы , cast(sys_date_create_or_update as date) as start_dt , cast('9999-12-31' as date) as end_dt from s_grnplm_as_t_didsd_308_db_stg.b3080000460007_payments_2_0_account_dto as o inner join s_grnplm_as_t_didsd_308_db_stg.b3080000460016_inkasso_export_agreement_actual_dto as b on o.agreementreference = b.reference where 1 = 1 and o.registerid_uid is not null and coalesce(upper(o.systemid), '') = upper('reserve-factory') --инкассо импортное union all select o.registerid_uid as registry_id , o.registerid as host_registry_id , null::uuid as agr_escrow_id , o.agreementreference_uid as agr_id , o.accountevent_number as coa_num , '00000000-0000-0000-0000-0000fffffc10' as registry_type_id -- -1008^importinkasso^Имп. Инкассо , cast(sys_date_create_or_update as date) as start_dt , cast('9999-12-31' as date) as end_dt from s_grnplm_as_t_didsd_308_db_stg.b3080000460007_payments_2_0_account_dto as o inner join s_grnplm_as_t_didsd_308_db_stg.b3080000460017_inkasso_import_agreement_actual_dto as b on o.agreementreference = b.reference where 1 = 1 and o.registerid_uid is not null and coalesce(upper(o.systemid), '') <> upper('reserve-factory') union all select o.registerid_uid as registry_id , o.registerid as host_registry_id , null::uuid as agr_escrow_id , o.agreementreference_uid as agr_id , o.accountevent_number as coa_num , '00000000-0000-0000-0000-0000fffffc12' as registry_type_id -- reserve^Резервы , cast(sys_date_create_or_update as date) as start_dt , cast('9999-12-31' as date) as as end_dt from s_grnplm_as_t_didsd_308_db_stg.b3080000460007_payments_2_0_account_dto as o inner join s_grnplm_as_t_didsd_308_db_stg.b3080000460017_inkasso_import_agreement_actual_dto as b on o.agreementreference = b.reference where 1 = 1 and o.registerid_uid is not null and coalesce(upper(o.systemid), '') = upper('reserve-factory') --рамбурсы union all select o.registerid_uid as registry_id , o.registerid as host_registry_id , null::uuid as agr_escrow_id , o.agreementreference_uid as agr_id , o.accountevent_number as coa_num , '00000000-0000-0000-0000-0000fffffc0e' as registry_type_id -- -1010^reimburs^Рамбурс , cast(sys_date_create_or_update as date) as start_dt , cast('9999-12-31' as date) as as end_dt from s_grnplm_as_t_didsd_308_db_stg.b3080000460007_payments_2_0_account_dto as o inner join s_grnplm_as_t_didsd_308_db_stg.b3080000460018_reimbursement_agreement_actual_dto as b on o.agreementreference = b.reference where 1 = 1 and o.registerid_uid is not null and coalesce(upper(o.systemid), '') <> upper('reserve-factory') union all select o.registerid_uid as registry_id , o.registerid as host_registry_id , null::uuid as agr_escrow_id , o.agreementreference_uid as agr_id , o.accountevent_number as coa_num , '00000000-0000-0000-0000-0000fffffc12' as registry_type_id -- reserve^Резервы , cast(sys_date_create_or_update as date) as start_dt , cast('9999-12-31' as date) as as end_dt from s_grnplm_as_t_didsd_308_db_stg.b3080000460007_payments_2_0_account_dto as o inner join s_grnplm_as_t_didsd_308_db_stg.b3080000460018_reimbursement_agreement_actual_dto as b on o.agreementreference = b.reference where 1 = 1 and o.registerid_uid is not null and coalesce(upper(o.systemid), '') = upper('reserve-factory') -- ГС union all select o.registerid_uid as registry_id , o.registerid as host_registry_id , null::uuid as agr_escrow_id , b.id_uid as agr_id , o.accountevent_number as coa_num , '00000000-0000-0000-0000-0000fffffc17' as registry_type_id -- '-1001^Генеральное соглашение ^ gs , cast(o.sys_date_create_or_update as date) as start_dt , cast('9999-12-31' as date) as end_dt from s_grnplm_as_t_didsd_308_db_stg.b3080000460007_payments_2_0_account_dto as o inner join s_grnplm_as_t_didsd_308_db_stg.b3080000460009_general_agreement_actual_dto as b on o.external_agreement_id = b.external_id where 1 = 1 and o.registerid_uid is not null and coalesce(upper(o.systemid), '') <> upper('reserve-factory') -- ГОДС union all select *, ROW_NUMBER() OVER (PARTITION BY a.registry_id ORDER BY a.start_dt DESC, st ) as rn from ( select 2 as st, recipientaccount_externalregistryid_uid as registry_id , recipientaccount_externalregistryid as host_registry_id , null::uuid as agr_escrow_id , externalid_uid as agr_id , null as coa_num , '00000000-0000-0000-0000-0000fffffc0c' as registry_type_id -- '-1001^ГОДС ^ gods , cast(sys_date_create_or_update as date) as start_dt , cast('9999-12-31' as date) as end_dt from s_grnplm_as_t_didsd_308_db_stg.b3080000460022_escrow_legalgk_gods_actual_dto where recipientaccount_externalregistryid is not null union all select 1 as st, o.registerid_uid as registry_id , o.registerid as host_registry_id , null::uuid as agr_escrow_id , b.externalid_uid as agr_id , o.accountevent_number as coa_num , '00000000-0000-0000-0000-0000fffffc0c' as registry_type_id -- '-1001^ГОДС ^ gods , cast(o.sys_date_create_or_update as date) as start_dt , cast('9999-12-31' as date) as end_dt from s_grnplm_as_t_didsd_308_db_stg.b3080000460007_payments_2_0_account_dto as o inner join s_grnplm_as_t_didsd_308_db_stg.b3080000460022_escrow_legalgk_gods_actual_dto as b on o.external_agreement_id = b.externalid where 1 = 1 and o.registerid_uid is not null and coalesce(upper(o.systemid), '') <> upper('reserve-factory') ) a where a.rn = 1 | V21: ="n308000046_"&IFERROR(VLOOKUP(D21,target_tables[],5,0),"<not found>") -> n308000046_registry | W21: Ключ | AF21: Снимок-снимок
A22: 190 | B22: Эскроу, ГС, Аккредитив, УПФ | C22: =IFERROR(VLOOKUP(D22,'Target tables'!A:B,2,0),"") -> Таблица регистров | D22: t_registry | E22: =IFERROR(VLOOKUP(D22&J22,'Target columns'!A:J,4,FALSE),"") -> TEXT | F22: =IFERROR(VLOOKUP(D22&J22,'Target columns'!A:J,7,FALSE),"") -> No | G22: =IFERROR(VLOOKUP(D22&J22,'Target columns'!A:J,8,FALSE),"") -> No | H22: =IFERROR(VLOOKUP(D22&J22,'Target columns'!A:J,5,FALSE),"") -> NULL | I22: =IFERROR(VLOOKUP(D22&J22,'Target columns'!A:J,10,FALSE),"") -> Идентификатор регистра в системе-источнике | J22: host_registry_id | K22: ETL | L22: text | M22: ID регистра счёта | N22: host_registry_id | V22: ="n308000046_"&IFERROR(VLOOKUP(D22,target_tables[],5,0),"<not found>") -> n308000046_registry | W22: -
A23: 195 | B23: Эскроу, ГС, Аккредитив, УПФ | C23: =IFERROR(VLOOKUP(D23,'Target tables'!A:B,2,0),"") -> Таблица регистров | D23: t_registry | E23: =IFERROR(VLOOKUP(D23&J23,'Target columns'!A:J,4,FALSE),"") -> UUID | F23: =IFERROR(VLOOKUP(D23&J23,'Target columns'!A:J,7,FALSE),"") -> No | G23: =IFERROR(VLOOKUP(D23&J23,'Target columns'!A:J,8,FALSE),"") -> Yes | H23: =IFERROR(VLOOKUP(D23&J23,'Target columns'!A:J,5,FALSE),"") -> NOT NULL | I23: =IFERROR(VLOOKUP(D23&J23,'Target columns'!A:J,10,FALSE),"") -> Тип регистра счета | J23: registry_type_id | K23: ETL | L23: uuid | M23: Тип регистра счета | N23: registry_type_id | V23: ="n308000046_"&IFERROR(VLOOKUP(D23,target_tables[],5,0),"<not found>") -> n308000046_registry | W23: -
A24: 200 | B24: Эскроу, ГС, Аккредитив, УПФ | C24: =IFERROR(VLOOKUP(D24,'Target tables'!A:B,2,0),"") -> Таблица регистров | D24: t_registry | E24: =IFERROR(VLOOKUP(D24&J24,'Target columns'!A:J,4,FALSE),"") -> UUID | F24: =IFERROR(VLOOKUP(D24&J24,'Target columns'!A:J,7,FALSE),"") -> No | G24: =IFERROR(VLOOKUP(D24&J24,'Target columns'!A:J,8,FALSE),"") -> Yes | H24: =IFERROR(VLOOKUP(D24&J24,'Target columns'!A:J,5,FALSE),"") -> NULL | I24: =IFERROR(VLOOKUP(D24&J24,'Target columns'!A:J,10,FALSE),"") -> Идентификатор договора эскроу | J24: agr_escrow_id | K24: ETL | L24: uuid | M24: Идентификатор договора эскроу | N24: agr_escrow_id | V24: ="n308000046_"&IFERROR(VLOOKUP(D24,target_tables[],5,0),"<not found>") -> n308000046_registry | W24: -
A25: 205 | B25: Эскроу, ГС, Аккредитив, УПФ | C25: =IFERROR(VLOOKUP(D25,'Target tables'!A:B,2,0),"") -> Таблица регистров | D25: t_registry | E25: =IFERROR(VLOOKUP(D25&J25,'Target columns'!A:J,4,FALSE),"") -> UUID | F25: =IFERROR(VLOOKUP(D25&J25,'Target columns'!A:J,7,FALSE),"") -> No | G25: =IFERROR(VLOOKUP(D25&J25,'Target columns'!A:J,8,FALSE),"") -> Yes | H25: =IFERROR(VLOOKUP(D25&J25,'Target columns'!A:J,5,FALSE),"") -> NULL | I25: =IFERROR(VLOOKUP(D25&J25,'Target columns'!A:J,10,FALSE),"") -> Идентификатор договора | J25: agr_id | K25: ETL | L25: uuid | M25: Идентификатор договора | N25: agr_id | V25: ="n308000046_"&IFERROR(VLOOKUP(D25,target_tables[],5,0),"<not found>") -> n308000046_registry | W25: - | AJ25: связь со счетом регистра по референсу
A26: 210 | B26: Эскроу, ГС, Аккредитив, УПФ | C26: =IFERROR(VLOOKUP(D26,'Target tables'!A:B,2,0),"") -> Таблица регистров | D26: t_registry | E26: =IFERROR(VLOOKUP(D26&J26,'Target columns'!A:J,4,FALSE),"") -> TEXT | F26: =IFERROR(VLOOKUP(D26&J26,'Target columns'!A:J,7,FALSE),"") -> No | G26: =IFERROR(VLOOKUP(D26&J26,'Target columns'!A:J,8,FALSE),"") -> No | H26: =IFERROR(VLOOKUP(D26&J26,'Target columns'!A:J,5,FALSE),"") -> NULL | I26: =IFERROR(VLOOKUP(D26&J26,'Target columns'!A:J,10,FALSE),"") -> Номер счета | J26: coa_num | K26: ETL | L26: text | M26: Номер счёта | N26: coa_num | V26: ="n308000046_"&IFERROR(VLOOKUP(D26,target_tables[],5,0),"<not found>") -> n308000046_registry | W26: -
A27: 220 | B27: Эскроу, ГС, Аккредитив, УПФ | C27: =IFERROR(VLOOKUP(D27,'Target tables'!A:B,2,0),"") -> Таблица регистров | D27: t_registry | E27: =IFERROR(VLOOKUP(D27&J27,'Target columns'!A:J,4,FALSE),"") -> DATE | F27: =IFERROR(VLOOKUP(D27&J27,'Target columns'!A:J,7,FALSE),"") -> No | G27: =IFERROR(VLOOKUP(D27&J27,'Target columns'!A:J,8,FALSE),"") -> No | H27: =IFERROR(VLOOKUP(D27&J27,'Target columns'!A:J,5,FALSE),"") -> NULL | I27: =IFERROR(VLOOKUP(D27&J27,'Target columns'!A:J,10,FALSE),"") -> Дата начала действия регистра | J27: start_dt | K27: ETL | N27: start_dt | V27: ="n308000046_"&IFERROR(VLOOKUP(D27,target_tables[],5,0),"<not found>") -> n308000046_registry | W27: Начало
A28: 230 | B28: Эскроу, ГС, Аккредитив, УПФ | C28: =IFERROR(VLOOKUP(D28,'Target tables'!A:B,2,0),"") -> Таблица регистров | D28: t_registry | E28: =IFERROR(VLOOKUP(D28&J28,'Target columns'!A:J,4,FALSE),"") -> DATE | F28: =IFERROR(VLOOKUP(D28&J28,'Target columns'!A:J,7,FALSE),"") -> No | G28: =IFERROR(VLOOKUP(D28&J28,'Target columns'!A:J,8,FALSE),"") -> No | H28: =IFERROR(VLOOKUP(D28&J28,'Target columns'!A:J,5,FALSE),"") -> NULL | I28: =IFERROR(VLOOKUP(D28&J28,'Target columns'!A:J,10,FALSE),"") -> Дата окончания действия регистра | J28: end_dt | K28: ETL | N28: end_dt | V28: ="n308000046_"&IFERROR(VLOOKUP(D28,target_tables[],5,0),"<not found>") -> n308000046_registry | W28: Конец
A29: 240 | B29: Эскроу | C29: =IFERROR(VLOOKUP(D29,'Target tables'!A:B,2,0),"") -> Справочник схем субсидирования | D29: t_escrow_scheme | E29: =IFERROR(VLOOKUP(D29&J29,'Target columns'!A:J,4,FALSE),"") -> UUID | F29: =IFERROR(VLOOKUP(D29&J29,'Target columns'!A:J,7,FALSE),"") -> Yes | G29: =IFERROR(VLOOKUP(D29&J29,'Target columns'!A:J,8,FALSE),"") -> No | H29: =IFERROR(VLOOKUP(D29&J29,'Target columns'!A:J,5,FALSE),"") -> NOT NULL | I29: =IFERROR(VLOOKUP(D29&J29,'Target columns'!A:J,10,FALSE),"") -> Идентификатор схемы субсидирования ставки | J29: escrow_scheme_id | K29: ETL | L29: uuid | M29: Схема субсидирования | N29: rateSubsidyScheme_agreement_uid | S29: select * from ( -- Эскроу 214 Схема субсидирования ставки select rateSubsidyScheme_agreement_uid, rateSubsidyScheme_agreement, case when rateSubsidyScheme_agreement = '1' then 'Схема 1' when rateSubsidyScheme_agreement = '2' then 'Схема 2' when rateSubsidyScheme_agreement = '0' then 'Схема 0' else 'Схема 00' end as rateSubsidyScheme_agreement_name, row_number() OVER (PARTITION BY rateSubsidyScheme_agreement ORDER BY sys_date_create_or_update DESC) AS rn from s_grnplm_as_t_didsd_308_db_stg.b3080000460001_escrow_legal214_agreement_actual_dto where rateSubsidyScheme_agreement is not null ) a where a.rn = 1 union ALL select * from ( select -- Эскроу ГКсхема распределения дохода profitscheme_uid as rateSubsidyScheme_agreement_uid, profitscheme as rateSubsidyScheme_agreement, case when profitscheme = 'DEPONENT' then 'Схема 0 – 100% депонент' when profitscheme = 'BENEFICIARY' then 'Схема 2 – 100% бенефициар' when profitscheme = 'EQUALLY' then 'Схема 1 – 50%/50% депонент/бенефициар' end as rateSubsidyScheme_agreement_name, row_number() OVER (PARTITION BY profitscheme ORDER BY sys_date_create_or_update DESC) AS rn from s_grnplm_as_t_didsd_308_db_stg.b3080000460002_escrow_legalgk_agreement_actual_dto where profitscheme is not null ) a where a.rn = 1 | V29: ="n308000046_"&IFERROR(VLOOKUP(D29,target_tables[],5,0),"<not found>") -> n308000046_escrow_scheme | W29: Ключ | AF29: Снимок-снимок
A30: 250 | B30: Эскроу | C30: =IFERROR(VLOOKUP(D30,'Target tables'!A:B,2,0),"") -> Справочник схем субсидирования | D30: t_escrow_scheme | E30: =IFERROR(VLOOKUP(D30&J30,'Target columns'!A:J,4,FALSE),"") -> TEXT | F30: =IFERROR(VLOOKUP(D30&J30,'Target columns'!A:J,7,FALSE),"") -> No | G30: =IFERROR(VLOOKUP(D30&J30,'Target columns'!A:J,8,FALSE),"") -> No | H30: =IFERROR(VLOOKUP(D30&J30,'Target columns'!A:J,5,FALSE),"") -> NULL | I30: =IFERROR(VLOOKUP(D30&J30,'Target columns'!A:J,10,FALSE),"") -> Код схемы субсидирования | J30: escrow_scheme_cd | K30: ETL | L30: text | M30: Схема субсидирования | N30: rateSubsidyScheme_agreement | V30: ="n308000046_"&IFERROR(VLOOKUP(D30,target_tables[],5,0),"<not found>") -> n308000046_escrow_scheme | W30: -
A31: 260 | B31: Эскроу | C31: =IFERROR(VLOOKUP(D31,'Target tables'!A:B,2,0),"") -> Справочник схем субсидирования | D31: t_escrow_scheme | E31: =IFERROR(VLOOKUP(D31&J31,'Target columns'!A:J,4,FALSE),"") -> TEXT | F31: =IFERROR(VLOOKUP(D31&J31,'Target columns'!A:J,7,FALSE),"") -> No | G31: =IFERROR(VLOOKUP(D31&J31,'Target columns'!A:J,8,FALSE),"") -> No | H31: =IFERROR(VLOOKUP(D31&J31,'Target columns'!A:J,5,FALSE),"") -> NULL | I31: =IFERROR(VLOOKUP(D31&J31,'Target columns'!A:J,10,FALSE),"") -> Наименование схемы субсидирования | J31: escrow_scheme_name | K31: ETL | L31: text | M31: Название схемы субсидирования | N31: rateSubsidyScheme_agreement_name | V31: ="n308000046_"&IFERROR(VLOOKUP(D31,target_tables[],5,0),"<not found>") -> n308000046_escrow_scheme | W31: -
A32: 270 | B32: Эскроу | C32: =IFERROR(VLOOKUP(D32,'Target tables'!A:B,2,0),"") -> Таблица связей кредитного договора с договором эскроу | D32: t_agr_escrow_agr_cred | E32: =IFERROR(VLOOKUP(D32&J32,'Target columns'!A:J,4,FALSE),"") -> UUID | F32: =IFERROR(VLOOKUP(D32&J32,'Target columns'!A:J,7,FALSE),"") -> Yes | G32: =IFERROR(VLOOKUP(D32&J32,'Target columns'!A:J,8,FALSE),"") -> Yes | H32: =IFERROR(VLOOKUP(D32&J32,'Target columns'!A:J,5,FALSE),"") -> NOT NULL | I32: =IFERROR(VLOOKUP(D32&J32,'Target columns'!A:J,10,FALSE),"") -> ИД договора эскроу | J32: agr_escrow_id | K32: b3080000460001_escrow_legal214_agreement_actual_dto | L32: =IFERROR(VLOOKUP(UPPER(K32&N32),source_columns[],4,0),"") | M32: =IFERROR(VLOOKUP(UPPER(K32&N32),source_columns[],7,0),"") | N32: escrowId_agreement_uid | S32: developerLoanAgrNumber_cred_agreement is not null or devLoanAgrKulId_agreement is not null | V32: ="n308000046_"&IFERROR(VLOOKUP(D32,target_tables[],5,0),"<not found>") -> n308000046_agr_escrow_agr_cred | W32: Ключ | AF32: Снимок-история
A33: 280 | B33: Эскроу | C33: =IFERROR(VLOOKUP(D33,'Target tables'!A:B,2,0),"") -> Таблица связей кредитного договора с договором эскроу | D33: t_agr_escrow_agr_cred | E33: =IFERROR(VLOOKUP(D33&J33,'Target columns'!A:J,4,FALSE),"") -> UUID | F33: =IFERROR(VLOOKUP(D33&J33,'Target columns'!A:J,7,FALSE),"") -> No | G33: =IFERROR(VLOOKUP(D33&J33,'Target columns'!A:J,8,FALSE),"") -> Yes | H33: =IFERROR(VLOOKUP(D33&J33,'Target columns'!A:J,5,FALSE),"") -> NULL | I33: =IFERROR(VLOOKUP(D33&J33,'Target columns'!A:J,10,FALSE),"") -> ИД кредитного договора с застройщиком | J33: agr_cred_id | K33: b3080000460001_escrow_legal214_agreement_actual_dto | L33: =IFERROR(VLOOKUP(UPPER(K33&N33),source_columns[],4,0),"") | M33: =IFERROR(VLOOKUP(UPPER(K33&N33),source_columns[],7,0),"") | N33: COALESCE (devLoanAgrKulId_agreement_uid, developerLoanAgrNumber_cred_agreement_uid) | V33: ="n308000046_"&IFERROR(VLOOKUP(D33,target_tables[],5,0),"<not found>") -> n308000046_agr_escrow_agr_cred | W33: -
A34: 290 | B34: Эскроу | C34: =IFERROR(VLOOKUP(D34,'Target tables'!A:B,2,0),"") -> Таблица связей кредитного договора с договором эскроу | D34: t_agr_escrow_agr_cred | E34: =IFERROR(VLOOKUP(D34&J34,'Target columns'!A:J,4,FALSE),"") -> DATE | F34: =IFERROR(VLOOKUP(D34&J34,'Target columns'!A:J,7,FALSE),"") -> Yes | G34: =IFERROR(VLOOKUP(D34&J34,'Target columns'!A:J,8,FALSE),"") -> No | H34: =IFERROR(VLOOKUP(D34&J34,'Target columns'!A:J,5,FALSE),"") -> NOT NULL | I34: =IFERROR(VLOOKUP(D34&J34,'Target columns'!A:J,10,FALSE),"") -> Дата начала действия связи между кредитным договором и договором эскроу | J34: start_dt | K34: b3080000460001_escrow_legal214_agreement_actual_dto | L34: =IFERROR(VLOOKUP(UPPER(K34&N34),source_columns[],4,0),"") | M34: =IFERROR(VLOOKUP(UPPER(K34&N34),source_columns[],7,0),"") | N34: cast(sys_date_create_or_update as date) | V34: ="n308000046_"&IFERROR(VLOOKUP(D34,target_tables[],5,0),"<not found>") -> n308000046_agr_escrow_agr_cred | W34: Начало
A35: 300 | B35: Эскроу | C35: =IFERROR(VLOOKUP(D35,'Target tables'!A:B,2,0),"") -> Таблица связей кредитного договора с договором эскроу | D35: t_agr_escrow_agr_cred | E35: =IFERROR(VLOOKUP(D35&J35,'Target columns'!A:J,4,FALSE),"") -> DATE | F35: =IFERROR(VLOOKUP(D35&J35,'Target columns'!A:J,7,FALSE),"") -> No | G35: =IFERROR(VLOOKUP(D35&J35,'Target columns'!A:J,8,FALSE),"") -> No | H35: =IFERROR(VLOOKUP(D35&J35,'Target columns'!A:J,5,FALSE),"") -> NULL | I35: =IFERROR(VLOOKUP(D35&J35,'Target columns'!A:J,10,FALSE),"") -> Дата окончания действия связи между кредитным договором и договором эскроу | J35: end_dt | K35: b3080000460001_escrow_legal214_agreement_actual_dto | L35: =IFERROR(VLOOKUP(UPPER(K35&N35),source_columns[],4,0),"") | M35: =IFERROR(VLOOKUP(UPPER(K35&N35),source_columns[],7,0),"") | N35: cast('9999-12-31' as date) | V35: ="n308000046_"&IFERROR(VLOOKUP(D35,target_tables[],5,0),"<not found>") -> n308000046_agr_escrow_agr_cred | W35: Конец
A36: 310 | B36: Эскроу | C36: =IFERROR(VLOOKUP(D36,'Target tables'!A:B,2,0),"") -> Таблица связей контрагентов с договором эскроу | D36: t_agr_escrow_cust | E36: =IFERROR(VLOOKUP(D36&J36,'Target columns'!A:J,4,FALSE),"") -> UUID | F36: =IFERROR(VLOOKUP(D36&J36,'Target columns'!A:J,7,FALSE),"") -> Yes | G36: =IFERROR(VLOOKUP(D36&J36,'Target columns'!A:J,8,FALSE),"") -> Yes | H36: =IFERROR(VLOOKUP(D36&J36,'Target columns'!A:J,5,FALSE),"") -> NOT NULL | I36: =IFERROR(VLOOKUP(D36&J36,'Target columns'!A:J,10,FALSE),"") -> Идентификатор договора эскроу | J36: agr_escrow_id | K36: b3080000460001_escrow_legal214_agreement_actual_dto | L36: =IFERROR(VLOOKUP(UPPER(K36&N36),source_columns[],4,0),"") -> uuid | M36: =IFERROR(VLOOKUP(UPPER(K36&N36),source_columns[],7,0),"") -> Идентификатор договора эскроу | N36: escrowId_agreement_uid | S36: legalEpkId_deponent is not null | V36: ="n308000046_"&IFERROR(VLOOKUP(D36,target_tables[],5,0),"<not found>") -> n308000046_agr_escrow_cust | W36: Ключ | AF36: Снимок-история
A37: 320 | B37: Эскроу | C37: =IFERROR(VLOOKUP(D37,'Target tables'!A:B,2,0),"") -> Таблица связей контрагентов с договором эскроу | D37: t_agr_escrow_cust | E37: =IFERROR(VLOOKUP(D37&J37,'Target columns'!A:J,4,FALSE),"") -> UUID | F37: =IFERROR(VLOOKUP(D37&J37,'Target columns'!A:J,7,FALSE),"") -> Yes | G37: =IFERROR(VLOOKUP(D37&J37,'Target columns'!A:J,8,FALSE),"") -> Yes | H37: =IFERROR(VLOOKUP(D37&J37,'Target columns'!A:J,5,FALSE),"") -> NOT NULL | I37: =IFERROR(VLOOKUP(D37&J37,'Target columns'!A:J,10,FALSE),"") -> Идентификатор контрагента | J37: cust_id | K37: b3080000460001_escrow_legal214_agreement_actual_dto | L37: =IFERROR(VLOOKUP(UPPER(K37&N37),source_columns[],4,0),"") -> uuid | M37: =IFERROR(VLOOKUP(UPPER(K37&N37),source_columns[],7,0),"") -> ЕПК id юр.лица депонента | N37: legalEpkId_deponent_uid | V37: ="n308000046_"&IFERROR(VLOOKUP(D37,target_tables[],5,0),"<not found>") -> n308000046_agr_escrow_cust | W37: -
A38: 330 | B38: Эскроу | C38: =IFERROR(VLOOKUP(D38,'Target tables'!A:B,2,0),"") -> Таблица связей контрагентов с договором эскроу | D38: t_agr_escrow_cust | E38: =IFERROR(VLOOKUP(D38&J38,'Target columns'!A:J,4,FALSE),"") -> DATE | F38: =IFERROR(VLOOKUP(D38&J38,'Target columns'!A:J,7,FALSE),"") -> Yes | G38: =IFERROR(VLOOKUP(D38&J38,'Target columns'!A:J,8,FALSE),"") -> No | H38: =IFERROR(VLOOKUP(D38&J38,'Target columns'!A:J,5,FALSE),"") -> NOT NULL | I38: =IFERROR(VLOOKUP(D38&J38,'Target columns'!A:J,10,FALSE),"") -> Дата начала действия | J38: start_dt | K38: b3080000460001_escrow_legal214_agreement_actual_dto | L38: =IFERROR(VLOOKUP(UPPER(K38&N38),source_columns[],4,0),"") | M38: =IFERROR(VLOOKUP(UPPER(K38&N38),source_columns[],7,0),"") | N38: cast(sys_date_create_or_update as date) | V38: ="n308000046_"&IFERROR(VLOOKUP(D38,target_tables[],5,0),"<not found>") -> n308000046_agr_escrow_cust | W38: Начало | AJ38: select agr_escrow_cust_type_id from s_grnplm_as_t_didsd_308_db_dwh.t_agr_escrow_cust_type where agr_escrow_cust_type_cd = 'deponent'
A39: 340 | B39: Эскроу | C39: =IFERROR(VLOOKUP(D39,'Target tables'!A:B,2,0),"") -> Таблица связей контрагентов с договором эскроу | D39: t_agr_escrow_cust | E39: =IFERROR(VLOOKUP(D39&J39,'Target columns'!A:J,4,FALSE),"") -> DATE | F39: =IFERROR(VLOOKUP(D39&J39,'Target columns'!A:J,7,FALSE),"") -> No | G39: =IFERROR(VLOOKUP(D39&J39,'Target columns'!A:J,8,FALSE),"") -> No | H39: =IFERROR(VLOOKUP(D39&J39,'Target columns'!A:J,5,FALSE),"") -> NULL | I39: =IFERROR(VLOOKUP(D39&J39,'Target columns'!A:J,10,FALSE),"") -> Дата окончания действия | J39: end_dt | K39: b3080000460001_escrow_legal214_agreement_actual_dto | L39: =IFERROR(VLOOKUP(UPPER(K39&N39),source_columns[],4,0),"") | M39: =IFERROR(VLOOKUP(UPPER(K39&N39),source_columns[],7,0),"") | N39: cast('9999-12-31' as date) | V39: ="n308000046_"&IFERROR(VLOOKUP(D39,target_tables[],5,0),"<not found>") -> n308000046_agr_escrow_cust | W39: Конец
A40: 350 | B40: Эскроу | C40: =IFERROR(VLOOKUP(D40,'Target tables'!A:B,2,0),"") -> Таблица связей контрагентов с договором эскроу | D40: t_agr_escrow_cust | E40: =IFERROR(VLOOKUP(D40&J40,'Target columns'!A:J,4,FALSE),"") -> UUID | F40: =IFERROR(VLOOKUP(D40&J40,'Target columns'!A:J,7,FALSE),"") -> Yes | G40: =IFERROR(VLOOKUP(D40&J40,'Target columns'!A:J,8,FALSE),"") -> Yes | H40: =IFERROR(VLOOKUP(D40&J40,'Target columns'!A:J,5,FALSE),"") -> NOT NULL | I40: =IFERROR(VLOOKUP(D40&J40,'Target columns'!A:J,10,FALSE),"") -> Роль клиента в договоре - ID | J40: agr_escrow_cust_type_id | K40: b3080000460001_escrow_legal214_agreement_actual_dto | L40: =IFERROR(VLOOKUP(UPPER(K40&N40),source_columns[],4,0),"") | M40: =IFERROR(VLOOKUP(UPPER(K40&N40),source_columns[],7,0),"") | N40: 00000000-0000-0000-0000-0000fffffc16 -- Депонент | V40: ="n308000046_"&IFERROR(VLOOKUP(D40,target_tables[],5,0),"<not found>") -> n308000046_agr_escrow_cust | W40: Ключ
A41: 360 | B41: Эскроу | C41: =IFERROR(VLOOKUP(D41,'Target tables'!A:B,2,0),"") -> Таблица связей контрагентов с договором эскроу | D41: t_agr_escrow_cust | E41: =IFERROR(VLOOKUP(D41&J41,'Target columns'!A:J,4,FALSE),"") -> UUID | F41: =IFERROR(VLOOKUP(D41&J41,'Target columns'!A:J,7,FALSE),"") -> Yes | G41: =IFERROR(VLOOKUP(D41&J41,'Target columns'!A:J,8,FALSE),"") -> Yes | H41: =IFERROR(VLOOKUP(D41&J41,'Target columns'!A:J,5,FALSE),"") -> NOT NULL | I41: =IFERROR(VLOOKUP(D41&J41,'Target columns'!A:J,10,FALSE),"") -> Идентификатор договора эскроу | J41: agr_escrow_id | K41: b3080000460001_escrow_legal214_agreement_actual_dto | L41: =IFERROR(VLOOKUP(UPPER(K41&N41),source_columns[],4,0),"") -> uuid | M41: =IFERROR(VLOOKUP(UPPER(K41&N41),source_columns[],7,0),"") -> Идентификатор договора эскроу | N41: escrowId_agreement_uid | S41: legalEpkId_beneficiary is not null | V41: ="n308000046_"&IFERROR(VLOOKUP(D41,target_tables[],5,0),"<not found>") -> n308000046_agr_escrow_cust | W41: Ключ | AF41: Снимок-история
...

Sheet Source columns
D1: =COLUMN() -> 4 | E1: =COLUMN() -> 5 | F1: =COLUMN() -> 6 | G1: =COLUMN() -> 7 | J1: Проверка соответствия типов S2T
A2: Seek | B2: Название таблицы STAGE | C2: Название поля | D2: Тип поля | E2: Первичный ключ | F2: NULL? | G2: Описание поля | H2: Описание таблицы | I2: Опции проекта | J2: Seek | K2: Тип поля
A3: =source_columns[[#This Row],[Название таблицы STAGE]]&source_columns[[#This Row],[Название поля]] -> b3080000460001_escrow_legal214_agreement_actual_dtoescrowId_agreement | B3: b3080000460001_escrow_legal214_agreement_actual_dto | C3: escrowId_agreement | D3: text | E3: YES | F3: NOT NULL | G3: Идентификатор договора эскроу
